Workbook

Sheet 006. Cuadro Comparativo APUs
E1: BUENO FERRO | I1: PABLO ESPINOSA | M1: MUÑOZ FREILE | Q1: RESUMEN
A2: CÓDIGO | B2: DESCRIPCIÓN | C2: UNIDAD | E2: CANTIDAD | F2: PRECIO UNITARIO | G2: PRECIO TOTAL | I2: CANTIDAD | J2: PRECIO UNITARIO | K2: PRECIO TOTAL | M2: CANTIDAD | N2: PRECIO UNITARIO | O2: PRECIO TOTAL | Q2: CANTIDAD x UNIDAD
A4: 01. PRELIMINARES
N5: IVA
A6: 01.01.01 | B6: Replanteo Topográfico Ejes Estructurales y movimiento tierras | C6: Glb | N6: 0
A8: MATERIALES
G9: =+E9*F9 -> 0 | K9: =+I9*J9 -> 0 | O9: =+M9*N9 -> 0
G10: =+E10*F10 -> 0 | K10: =+I10*J10 -> 0 | O10: =+M10*N10 -> 0
A11: MANO DE OBRA
B12: M. Replanteo Topográfico Ejes Estructurales y movimiento tierras | C12: Glb | E12: 1 | F12: 240 | G12: =+E12*F12 -> 240 | I12: 1 | J12: 120 | K12: =+I12*J12 -> 120 | M12: 1 | N12: 120 | O12: =+M12*N12 -> 120
G13: =+E13*F13 -> 0 | K13: =+I13*J13 -> 0 | O13: =+M13*N13 -> 0
A14: EQUIPO
E15: =+E43 -> 325.39 | G15: =+E15*F15 -> 0 | I15: =+I43 -> 249.11 | K15: =+I15*J15 -> 0 | M15: =+M43 -> 951.68 | O15: =+M15*N15 -> 0
G16: =+E16*F16 -> 0 | K16: =+I16*J16 -> 0 | O16: =+M16*N16 -> 0
A18: TOTAL COSTO APU | G18: =SUM(G8:G17) -> 240 | K18: =SUM(K6:K16) -> 120 | O18: =SUM(O6:O16) -> 120
A19: COSTO UNITARIO APU | G19: =+G18/E15 -> 0.73757645 | K19: =+K18/I15 -> 0.48171491 | O19: =+O18/M15 -> 0.1260928
A23: 01.01.02 | B23: Replanteo Y Nivelación | C23: m2
A25: MATERIALES
B26: Alambre galvanizado N 14 (Alambre galvanizado N 14) | C26: rollo | E26: 1 | F26: 83.81 | G26: =+E26*F26 -> 83.81 | K26: =+I26*J26 -> 0 | O26: =+M26*N26 -> 0 | Q26: =+E26/$E$43 -> 0.0030732352
B27: Broca Madera Titanio3/8" (Broca Madera Titanio3/8") | C27: Uni. | G27: =+E27*F27 -> 0 | K27: =+I27*J27 -> 0 | M27: 1 | N27: 1.03 | O27: =+M27*N27 -> 1.03 | Q27: =+M27/M43 -> 0.0010507734
B28: Caoba Roja (Caoba Roja) | C28: lb | E28: 19.5 | F28: 0.532 | G28: =+E28*F28 -> 10.374 | I28: 4.42 | J28: 0.5 | K28: =+I28*J28 -> 2.21 | M28: 8.11 | N28: 0.54 | O28: =+M28*N28 -> 4.3794 | Q28: =+(E28+I28+M28)/($E$43+$I$43+$M$43) -> 0.02098704
B29: Cementina (Cementina) | C29: saco | E29: 7 | F29: 1.488 | G29: =+E29*F29 -> 10.416 | I29: 9 | J29: 1.47 | K29: =+I29*J29 -> 13.23 | M29: 15 | N29: 1.95 | O29: =+M29*N29 -> 29.25 | Q29: =+(E29+I29+M29)/($E$43+$I$43+$M$43) -> 0.020312152
B30: Clavos de acero 2'' (Clavos de acero 2'') | C30: Kg. | E30: 1.5 | F30: 3.41 | G30: =+E30*F30 -> 5.115 | K30: =+I30*J30 -> 0 | O30: =+M30*N30 -> 0 | Q30: =+E30/E43 -> 0.0046098528
B31: Clavos de acero 21/2'' (Clavos de acero 21/2'') | C31: Kg. | E31: 2 | F31: 3.417 | G31: =+E31*F31 -> 6.834 | I31: 1 | J31: 3.94 | K31: =+I31*J31 -> 3.94 | M31: 0.5 | N31: 3.94 | O31: =+M31*N31 -> 1.97 | Q31: =+(E31+I31+M31)/($E$43+$I$43+$M$43) -> 0.0022933075
B32: Clavos galvanizados 2'' (Clavos galvanizados 2'') | C32: Kg. | E32: 3.5 | F32: 1.49 | G32: =+E32*F32 -> 5.215 | I32: 2 | J32: 2.08 | K32: =+I32*J32 -> 4.16 | O32: =+M32*N32 -> 0 | Q32: =+(E32+I32)/($E$43+$I$43) -> 0.0095735422
B33: Clavos galvanizados 2 1/2'' (Clavos galvanizados 2 1/2'') | C33: Kg. | E33: 4 | F33: 1.438 | G33: =+E33*F33 -> 5.752 | K33: =+I33*J33 -> 0 | M33: 0.25 | N33: 2 | O33: =+M33*N33 -> 0.5 | Q33: =+E33/E43 -> 0.012292941
B34: Clavos galvanizados 3" (Clavos galvanizados 3") | C34: Kg. | G34: =+E34*F34 -> 0 | I34: 1 | J34: 2.41 | K34: =+I34*J34 -> 2.41 | O34: =+M34*N34 -> 0 | Q34: =+I34/I43 -> 0.0040142909
B35: Cuartón 6 x 4 de eucalipto (Cuartón 6 x 4 de eucalipto) | C35: Uni. | G35: =+E35*F35 -> 0 | K35: =+I35*J35 -> 0 | M35: 13 | N35: 2.15 | O35: =+M35*N35 -> 27.95 | Q35: =+M35/M43 -> 0.013660054
B36: Manguera transparente (Manguera transparente) | C36: ml | G36: =+E36*F36 -> 0 | I36: 25 | J36: 0.4 | K36: =+I36*J36 -> 10 | O36: =+M36*N36 -> 0 | Q36: =+I36/I43 -> 0.10035727
B37: Pingos de 2.5 mts (Pingos de 2.5 mts) | C37: Uni. | E37: 19 | F37: 1.1275 | G37: =+E37*F37 -> 21.4225 | I37: 10 | J37: 1.1 | K37: =+I37*J37 -> 11 | M37: 3 | N37: 1.1 | O37: =+M37*N37 -> 3.3 | Q37: =+(E37+I37+M37)/($E$43+$I$43+$M$43) -> 0.020967383
B38: Pingos de 3 mts (Pingos de 3 mts) | C38: Uni. | G38: =+E38*F38 -> 0 | I38: 10 | J38: 1.08 | K38: =+I38*J38 -> 10.8 | M38: 5 | N38: 1.2 | O38: =+M38*N38 -> 6 | Q38: =+(I38+M38)/($I$43+$M$43) -> 0.012491776
B39: Riel de eucalipto (Riel de eucalipto) | C39: Uni. | E39: 32 | F39: 1.767 | G39: =+E39*F39 -> 56.544 | I39: 10 | J39: 1.82 | K39: =+I39*J39 -> 18.2 | O39: =+M39*N39 -> 0 | Q39: =+(E39+I39)/($E$43+$I$43) -> 0.07310705
B40: Spray Rojo (Spray Rojo) | C40: Uni. | E40: 3 | F40: 1.4845 | G40: =+E40*F40 -> 4.4535 | I40: 5 | J40: 1.78 | K40: =+I40*J40 -> 8.9 | M40: 2 | N40: 2.22 | O40: =+M40*N40 -> 4.44 | Q40: =+(E40+I40+M40)/($E$43+$I$43+$M$43) -> 0.0065523071
B41: Tablas de Monte (Tablas de Monte) | C41: Uni. | E41: 7 | F41: 2.34 | G41: =+E41*F41 -> 16.38 | I41: 10 | J41: 2.44 | K41: =+I41*J41 -> 24.4 | O41: =+M41*N41 -> 0 | Q41: =+(E41+I41)/($E$43+$I$43) -> 0.029590949
A42: MANO DE OBRA
B43: M. Replanteo Y Nivelación | C43: m2 | E43: 325.39 | F43: 0.72 | G43: =+E43*F43 -> 234.2808 | I43: 249.11 | J43: 0.72 | K43: =+I43*J43 -> 179.3592 | M43: 951.68 | N43: 0.89 | O43: =+M43*N43 -> 846.9952
G44: =+E44*F44 -> 0 | K44: =+I44*J44 -> 0 | O44: =+M44*N44 -> 0
G45: =+E45*F45 -> 0 | K45: =+I45*J45 -> 0 | O45: =+M45*N45 -> 0
A46: EQUIPO
G47: =+E47*F47 -> 0 | K47: =+I47*J47 -> 0 | O47: =+M47*N47 -> 0
...

Sheet Reporte Decisiones Pendientes
A1: REPORTE DE DECISIONES PENDIENTES — Revisión con Ingenieros
A2: Insumos con dispersión de precio entre obras. Marcar 'Valor Adoptado' y firmar.
A4: Categoría | B4: APU | C4: Sección | D4: Insumo | E4: Unidad | F4: PU BUENO FERRO | G4: PU PABLO ESPINOSA | H4: PU MUÑOZ FREILE | I4: Desv % | J4: Valor Adoptado / Observación Ing.
A5: --- A - ERROR DE UNIDAD PROBABLE (5) ---
A6: A - ERROR DE UNIDAD PROBABLE | B6: 13.01.09 | C6: materiales | D6: Cable Gemelo Blanco 2X10 (Cable Gemelo Blanco 2X10) | E6: Rollo | G6: 99.11 | H6: 1.2 | I6: 81.59
A7: A - ERROR DE UNIDAD PROBABLE | B7: 01.01.08 | C7: materiales | D7: Tela Arpillera Verde 1.90m (Tela Arpillera Verde 1.90m (Rollo 100m)) | E7: rollo | F7: 46.93 | H7: 0.61 | I7: 75.93
A8: A - ERROR DE UNIDAD PROBABLE | B8: 13.01.02 | C8: materiales | D8: Detergente (Detergente) | E8: Kg. | F8: 1.77 | H8: 27.18 | I8: 14.36
A9: A - ERROR DE UNIDAD PROBABLE | B9: 03.03.04 | C9: materiales | D9: Disco diamante segmentado 9" (Disco diamante segmentado 9") | E9: Uni. | F9: 5.59 | H9: 71 | I9: 11.7
A10: A - ERROR DE UNIDAD PROBABLE | B10: 02.01.02 | C10: equipo | D10: M. Transporte desalojo de material a botadero | E10: m3 | G10: 36.78 | H10: 3.79 | I10: 8.7
A11: --- B - REQUIERE CRITERIO (17) ---
A12: B - REQUIERE CRITERIO | B12: 03.03.04 | C12: materiales | D12: Hormigón Premez. fc= 210 kg S/B (Hormigón Premezclado fc= 210 kg/cm2) | E12: m3 | F12: 71 | H12: 12.5 | I12: 4.68
A13: B - REQUIERE CRITERIO | B13: 13.01.02 | C13: mano_obra | D13: M. Limpieza Provisional (Durante la obra Material Y Personal) | E13: Glb | F13: 202.61 | G13: 1026.32 | H13: 880 | I13: 4.07
A14: B - REQUIERE CRITERIO | B14: 13.01.05 | C14: equipo | D14: Gafa Transparente Reforzada (Gafa Transparente Reforzada) | E14: Uni. | G14: 1.82 | H14: 0.48 | I14: 2.79
A15: B - REQUIERE CRITERIO | B15: 13.01.09 | C15: materiales | D15: Manguera de Jardin con Acce (Manguera de Jardin con Accesorios) | E15: ml | G15: 0.31 | H15: 1.14 | I15: 2.68
A16: B - REQUIERE CRITERIO | B16: 03.02.02 | C16: materiales | D16: Cemento Campeón (Cemento Campeón) | E16: qq | F16: 6.64 | G16: 1.9366667 | H16: 6.71 | I16: 2.46
A17: B - REQUIERE CRITERIO | B17: 01.01.05 | C17: materiales | D17: Aldaba Galvanizada 2'' (Aldaba Galvanizada 2'') | E17: Uni. | F17: 0.32 | G17: 1.03 | I17: 2.22
A18: B - REQUIERE CRITERIO | B18: 05.01.05 | C18: materiales | D18: Broca Concreto 1/2X30cm (Broca Concreto 1/2X30cm) | E18: Uni. | F18: 5.1 | H18: 1.89 | I18: 1.7
A19: B - REQUIERE CRITERIO | B19: 04.01.08 | C19: materiales | D19: Clavos de acero 2'' (Clavos de acero 2'') | E19: Kg. | F19: 3.02 | G19: 7.2 | I19: 1.38
A20: B - REQUIERE CRITERIO | B20: 04.01.02 | C20: mano_obra | D20: M. Encofrado y Desencofrado de Vigas | E20: m2 | F20: 25.87 | G20: 11 | H20: 11.5 | I20: 1.35
A21: B - REQUIERE CRITERIO | B21: 05.01.06 | C21: materiales | D21: Clavos de acero 2'' (Clavos de acero 2'') | E21: Kg. | F21: 3.06 | G21: 7.2 | I21: 1.35
A22: B - REQUIERE CRITERIO | B22: 13.01.09 | C22: materiales | D22: Sierra Circular Dewalt 71/4 180 (Sierra Circular Dewalt 71/4 1800W DWE575-B3) | E22: Uni. | G22: 278.69 | H22: 118.54 | I22: 1.35
A23: B - REQUIERE CRITERIO | B23: 13.01.09 | C23: materiales | D23: Tanque para combustible 20lts. (Tanque para combustible rojo 20lts.) | E23: Uni. | G23: 17.48 | H23: 7.51 | I23: 1.33
A24: B - REQUIERE CRITERIO | B24: 13.01.05 | C24: equipo | D24: Casco (Casco) | E24: Uni. | F24: 9.52 | G24: 4.13 | H24: 4.12 | I24: 1.31
A25: B - REQUIERE CRITERIO | B25: 05.01.05 | C25: materiales | D25: Disco diamante segmentado 9" (Disco diamante segmentado 9") | E25: Uni. | F25: 5.31 | H25: 2.46 | I25: 1.16
A26: B - REQUIERE CRITERIO | B26: 13.01.09 | C26: materiales | D26: Taipe 3m 3/4 x2 Negro (Taipe 3m 3/4 x2 Negro) | E26: Uni. | F26: 0.906 | G26: 0.44 | H26: 0.85 | I26: 1.06
A27: B - REQUIERE CRITERIO | B27: 01.01.01 | C27: mano_obra | D27: M. Replanteo Topográfico Ejes Estructurales y movimiento tierras | E27: Glb | F27: 240 | G27: 120 | H27: 120 | I27: 1
A28: B - REQUIERE CRITERIO | B28: 03.03.15 | C28: equipo | D28: M. Pruebas De Laboratorio | E28: Glb | F28: 60 | G28: 40 | H28: 80 | I28: 1
A29: --- C - VARIACIÓN MEDIA-ALTA (informativo) (6) ---
A30: C - VARIACIÓN MEDIA-ALTA (informativo) | B30: 13.01.02 | C30: materiales | D30: Escoba de coco (Escoba de coco) | E30: Uni. | F30: 1.525 | G30: 2.89 | H30: 2.95 | I30: 0.93
A31: C - VARIACIÓN MEDIA-ALTA (informativo) | B31: 05.01.10 | C31: materiales | D31: Arena Fina (Arena Fina) | F31: 6.59 | H31: 12.27 | I31: 0.86
A32: C - VARIACIÓN MEDIA-ALTA (informativo) | B32: 03.03.07 | C32: materiales | D32: Ripio (Ripio) | E32: m3 | F32: 21.7 | G32: 11.83 | I32: 0.83
A33: C - VARIACIÓN MEDIA-ALTA (informativo) | B33: 05.01.05 | C33: materiales | D33: Sikadur Primer 32 | E33: Uni. | F33: 52.87 | H33: 87.71 | I33: 0.66
A34: C - VARIACIÓN MEDIA-ALTA (informativo) | B34: 03.02.02 | C34: materiales | D34: Disco Corte Madera 7 (Disco Corte Madera 7) | E34: Uni. | F34: 12.13 | H34: 7.4 | I34: 0.64
A35: C - VARIACIÓN MEDIA-ALTA (informativo) | B35: 13.01.05 | C35: equipo | D35: Cinta amarilla Precaución 200MT (Cinta amarilla Precaución 200MT) | E35: mts. | F35: 0.0164 | G35: 0.0222 | H35: 0.0265 | I35: 0.62

Sheet APU Estándar
A1: PROPUESTA DE APU ESTÁNDAR
A2: Construido a partir del análisis comparativo de 3 obras: BUENO FERRO · PABLO ESPINOSA · MUÑOZ FREILE
A3: Leyenda: 🟡 Fila amarilla = dato de 1 sola obra (cobertura única) | 🟠 Fila naranja = dispersión alta, revisar en hoja 'Reporte Decisiones Pendientes' | 🔴 Rojo = error de unidad probable
A5: 01. PRELIMINARES
A6: 01.01.01 | B6: Replanteo Topográfico Ejes Estructurales y movimiento tierras | C6: Glb | D6: Cant/Rend | E6: P.Unit | F6: Subtotal | G6: Cant BF | H6: PU BF | I6: Cant PE | J6: PU PE | K6: Cant MF | L6: PU MF | M6: Observación
A7: MANO DE OBRA
B8: M. Replanteo Topográfico Ejes Estructurales y movimiento tierras | C8: Glb | D8: =IFERROR(INDEX('BD Rendimientos'!G:G,MATCH("01.01.01|M. Replanteo Topográfico Ejes Estructurales y movimiento tierras|Glb|mano_obra",'BD Rendimientos'!L:L,0)),"") -> 1 | E8: =IFERROR(INDEX('BD Mano de Obra'!D:D,MATCH("M. Replanteo Topográfico Ejes Estructurales y movimiento tierras",'BD Mano de Obra'!B:B,0)),"") -> 160 | F8: =IFERROR(D8*E8,"") -> 160 | G8: 1 | H8: 240 | I8: 1 | J8: 120 | K8: 1 | L8: 120
A9: EQUIPO
B10: COSTO UNITARIO APU ESTÁNDAR | C10: Glb | F10: =SUM(F8) -> 160 | H10: 0.73757645 | J10: 0.48171491 | L10: 0.1260928 | M10: CU observados →
A12: 01.01.02 | B12: Replanteo Y Nivelación | C12: m2 | D12: Cant/Rend | E12: P.Unit | F12: Subtotal | G12: Cant BF | H12: PU BF | I12: Cant PE | J12: PU PE | K12: Cant MF | L12: PU MF | M12: Observación
A13: MATERIALES
B14: Alambre galvanizado N 14 | C14: rollo | D14: =IFERROR(INDEX('BD Rendimientos'!G:G,MATCH("01.01.02|Alambre galvanizado N 14|rollo|materiales",'BD Rendimientos'!L:L,0)),"") -> 0.0030732352 | E14: =IFERROR(INDEX('BD Materiales'!D:D,MATCH("Alambre galvanizado N 14",'BD Materiales'!B:B,0)),"") -> 82.9725 | F14: =IFERROR(D14*E14,"") -> 0.25499401 | G14: 1 | H14: 83.81 | M14: PU: cobertura única
B15: Broca Madera Titanio3/8" | C15: Uni. | D15: =IFERROR(INDEX('BD Rendimientos'!G:G,MATCH("01.01.02|Broca Madera Titanio3/8""|Uni.|materiales",'BD Rendimientos'!L:L,0)),"") -> 0.0010507734 | E15: =IFERROR(INDEX('BD Materiales'!D:D,MATCH("Broca Madera Titanio3/8""",'BD Materiales'!B:B,0)),"") -> 1.02 | F15: =IFERROR(D15*E15,"") -> 0.0010717888 | K15: 1 | L15: 1.03 | M15: PU: cobertura única
B16: Caoba Roja | C16: lb | D16: =IFERROR(INDEX('BD Rendimientos'!G:G,MATCH("01.01.02|Caoba Roja|lb|materiales",'BD Rendimientos'!L:L,0)),"") -> 0.017743166 | E16: =IFERROR(INDEX('BD Materiales'!D:D,MATCH("Caoba Roja",'BD Materiales'!B:B,0)),"") -> 0.517 | F16: =IFERROR(D16*E16,"") -> 0.0091732167 | G16: 19.5 | H16: 0.532 | I16: 4.42 | J16: 0.5 | K16: 8.11 | L16: 0.54 | M16: | Rend: Rendimiento disperso
B17: Cementina | C17: saco | D17: =IFERROR(INDEX('BD Rendimientos'!G:G,MATCH("01.01.02|Cementina|saco|materiales",'BD Rendimientos'!L:L,0)),"") -> 0.024467622 | E17: =IFERROR(INDEX('BD Materiales'!D:D,MATCH("Cementina",'BD Materiales'!B:B,0)),"") -> 1.636 | F17: =IFERROR(D17*E17,"") -> 0.040029029 | G17: 7 | H17: 1.488 | I17: 9 | J17: 1.47 | K17: 15 | L17: 1.95
B18: Clavos de acero 2'' | C18: Kg. | D18: =IFERROR(INDEX('BD Rendimientos'!G:G,MATCH("01.01.02|Clavos de acero 2''|Kg.|materiales",'BD Rendimientos'!L:L,0)),"") -> 0.0046098528 | E18: =IFERROR(INDEX('BD Materiales'!D:D,MATCH("Clavos de acero 2''",'BD Materiales'!B:B,0)),"") -> 3.245 | F18: =IFERROR(D18*E18,"") -> 0.014958972 | G18: 1.5 | H18: 3.41 | M18: PU: cobertura única
B19: Clavos de acero 21/2'' | C19: Kg. | D19: =IFERROR(INDEX('BD Rendimientos'!G:G,MATCH("01.01.02|Clavos de acero 21/2''|Kg.|materiales",'BD Rendimientos'!L:L,0)),"") -> 0.0040142909 | E19: =IFERROR(INDEX('BD Materiales'!D:D,MATCH("Clavos de acero 21/2''",'BD Materiales'!B:B,0)),"") -> 3.5215 | F19: =IFERROR(D19*E19,"") -> 0.014136325 | G19: 2 | H19: 3.417 | I19: 1 | J19: 3.94 | K19: 0.5 | L19: 3.94 | M19: | Rend: Rendimiento disperso
B20: Clavos galvanizados 2'' | C20: Kg. | D20: =IFERROR(INDEX('BD Rendimientos'!G:G,MATCH("01.01.02|Clavos galvanizados 2''|Kg.|materiales",'BD Rendimientos'!L:L,0)),"") -> 0.0093924525 | E20: =IFERROR(INDEX('BD Materiales'!D:D,MATCH("Clavos galvanizados 2''",'BD Materiales'!B:B,0)),"") -> 1.9257895 | F20: =IFERROR(D20*E20,"") -> 0.018087886 | G20: 3.5 | H20: 1.49 | I20: 2 | J20: 2.08
B21: Clavos galvanizados 2 1/2'' | C21: Kg. | D21: =IFERROR(INDEX('BD Rendimientos'!G:G,MATCH("01.01.02|Clavos galvanizados 2 1/2''|Kg.|materiales",'BD Rendimientos'!L:L,0)),"") -> 0.0062778171 | E21: =IFERROR(INDEX('BD Materiales'!D:D,MATCH("Clavos galvanizados 2 1/2''",'BD Materiales'!B:B,0)),"") -> 1.8223333 | F21: =IFERROR(D21*E21,"") -> 0.011440275 | G21: 4 | H21: 1.438 | K21: 0.25 | L21: 2 | M21: | Rend: Rendimiento disperso
B22: Clavos galvanizados 3" | C22: Kg. | D22: =IFERROR(INDEX('BD Rendimientos'!G:G,MATCH("01.01.02|Clavos galvanizados 3""|Kg.|materiales",'BD Rendimientos'!L:L,0)),"") -> 0.0040142909 | E22: =IFERROR(INDEX('BD Materiales'!D:D,MATCH("Clavos galvanizados 3""",'BD Materiales'!B:B,0)),"") -> 2.415 | F22: =IFERROR(D22*E22,"") -> 0.0096945125 | I22: 1 | J22: 2.41 | M22: PU: cobertura única
B23: Cuartón 6 x 4 de eucalipto | C23: Uni. | D23: =IFERROR(INDEX('BD Rendimientos'!G:G,MATCH("01.01.02|Cuartón 6 x 4 de eucalipto|Uni.|materiales",'BD Rendimientos'!L:L,0)),"") -> 0.013660054 | E23: =IFERROR(INDEX('BD Materiales'!D:D,MATCH("Cuartón 6 x 4 de eucalipto",'BD Materiales'!B:B,0)),"") -> 2.15 | F23: =IFERROR(D23*E23,"") -> 0.029369116 | K23: 13 | L23: 2.15 | M23: PU: cobertura única
B24: Manguera transparente | C24: ml | D24: =IFERROR(INDEX('BD Rendimientos'!G:G,MATCH("01.01.02|Manguera transparente|ml|materiales",'BD Rendimientos'!L:L,0)),"") -> 0.10035727 | E24: =IFERROR(INDEX('BD Materiales'!D:D,MATCH("Manguera transparente",'BD Materiales'!B:B,0)),"") -> 0.4 | F24: =IFERROR(D24*E24,"") -> 0.040142909 | I24: 25 | J24: 0.4 | M24: PU: cobertura única
B25: Pingos de 2.5 mts | C25: Uni. | D25: =IFERROR(INDEX('BD Rendimientos'!G:G,MATCH("01.01.02|Pingos de 2.5 mts|Uni.|materiales",'BD Rendimientos'!L:L,0)),"") -> 0.040142909 | E25: =IFERROR(INDEX('BD Materiales'!D:D,MATCH("Pingos de 2.5 mts",'BD Materiales'!B:B,0)),"") -> 1.1206818 | F25: =IFERROR(D25*E25,"") -> 0.044987428 | G25: 19 | H25: 1.1275 | I25: 10 | J25: 1.1 | K25: 3 | L25: 1.1 | M25: | Rend: Rendimiento disperso
B26: Pingos de 3 mts | C26: Uni. | D26: =IFERROR(INDEX('BD Rendimientos'!G:G,MATCH("01.01.02|Pingos de 3 mts|Uni.|materiales",'BD Rendimientos'!L:L,0)),"") -> 0.022698388 | E26: =IFERROR(INDEX('BD Materiales'!D:D,MATCH("Pingos de 3 mts",'BD Materiales'!B:B,0)),"") -> 1.14 | F26: =IFERROR(D26*E26,"") -> 0.025876162 | I26: 10 | J26: 1.08 | K26: 5 | L26: 1.2 | M26: | Rend: Rendimiento disperso
B27: Riel de eucalipto | C27: Uni. | D27: =IFERROR(INDEX('BD Rendimientos'!G:G,MATCH("01.01.02|Riel de eucalipto|Uni.|materiales",'BD Rendimientos'!L:L,0)),"") -> 0.069243217 | E27: =IFERROR(INDEX('BD Materiales'!D:D,MATCH("Riel de eucalipto",'BD Materiales'!B:B,0)),"") -> 1.81825 | F27: =IFERROR(D27*E27,"") -> 0.12590148 | G27: 32 | H27: 1.767 | I27: 10 | J27: 1.82
B28: Spray Rojo | C28: Uni. | D28: =IFERROR(INDEX('BD Rendimientos'!G:G,MATCH("01.01.02|Spray Rojo|Uni.|materiales",'BD Rendimientos'!L:L,0)),"") -> 0.0092197056 | E28: =IFERROR(INDEX('BD Materiales'!D:D,MATCH("Spray Rojo",'BD Materiales'!B:B,0)),"") -> 1.8281667 | F28: =IFERROR(D28*E28,"") -> 0.016855158 | G28: 3 | H28: 1.4845 | I28: 5 | J28: 1.78 | K28: 2 | L28: 2.22 | M28: | Rend: Rendimiento disperso
B29: Tablas de Monte | C29: Uni. | D29: =IFERROR(INDEX('BD Rendimientos'!G:G,MATCH("01.01.02|Tablas de Monte|Uni.|materiales",'BD Rendimientos'!L:L,0)),"") -> 0.030827778 | E29: =IFERROR(INDEX('BD Materiales'!D:D,MATCH("Tablas de Monte",'BD Materiales'!B:B,0)),"") -> 2.4034926 | F29: =IFERROR(D29*E29,"") -> 0.074094335 | G29: 7 | H29: 2.34 | I29: 10 | J29: 2.44
A30: MANO DE OBRA
B31: M. Replanteo Y Nivelación | C31: m2 | D31: =IFERROR(INDEX('BD Rendimientos'!G:G,MATCH("01.01.02|M. Replanteo Y Nivelación|m2|mano_obra",'BD Rendimientos'!L:L,0)),"") -> 1 | E31: =IFERROR(INDEX('BD Mano de Obra'!D:D,MATCH("M. Replanteo Y Nivelación",'BD Mano de Obra'!B:B,0)),"") -> 0.77666667 | F31: =IFERROR(D31*E31,"") -> 0.77666667 | G31: 325.39 | H31: 0.72 | I31: 249.11 | J31: 0.72 | K31: 951.68 | L31: 0.89
B32: COSTO UNITARIO APU ESTÁNDAR | C32: m2 | F32: =SUM(F14,F15,F16,F17,F18,F19,F20,F21,F22,F23,F24,F25,F26,F27,F28,F29,F31) -> 1.5074793 | H32: 1.4155223 | J32: 1.1585613 | L32: 0.97282133 | M32: CU observados →
A34: 01.01.03 | B34: Instalaciones eléctricas provisionales | C34: Glb | D34: Cant/Rend | E34: P.Unit | F34: Subtotal | G34: Cant BF | H34: PU BF | I34: Cant PE | J34: PU PE | K34: Cant MF | L34: PU MF | M34: Observación
A35: MANO DE OBRA
B36: M. Instalaciones eléctricas provisionales | C36: Glb | D36: =IFERROR(INDEX('BD Rendimientos'!G:G,MATCH("01.01.03|M. Instalaciones eléctricas provisionales|Glb|mano_obra",'BD Rendimientos'!L:L,0)),"") -> 1 | E36: =IFERROR(INDEX('BD Mano de Obra'!D:D,MATCH("M. Instalaciones eléctricas provisionales",'BD Mano de Obra'!B:B,0)),"") -> 300 | F36: =IFERROR(D36*E36,"") -> 300 | G36: 300 | H36: 300 | J36: 300 | L36: 300 | M36: MO principal (reconstruida)
A37: EQUIPO
B38: COSTO UNITARIO APU ESTÁNDAR | C38: Glb | F38: =F36 -> 300 | H38: 0.92197056 | J38: 1.2042873 | L38: 0.31523201 | M38: CU observados →
A40: 01.01.04 | B40: Instalaciones hidrosanitarias provisionales | C40: Glb | D40: Cant/Rend | E40: P.Unit | F40: Subtotal | G40: Cant BF | H40: PU BF | I40: Cant PE | J40: PU PE | K40: Cant MF | L40: PU MF | M40: Observación
A41: MANO DE OBRA
B42: M. Instalaciones hidrosanitarias provisionales | C42: Glb | D42: =IFERROR(INDEX('BD Rendimientos'!G:G,MATCH("01.01.04|M. Instalaciones hidrosanitarias provisionales|Glb|mano_obra",'BD Rendimientos'!L:L,0)),"") -> 1 | E42: =IFERROR(INDEX('BD Mano de Obra'!D:D,MATCH("M. Instalaciones hidrosanitarias provisionales",'BD Mano de Obra'!B:B,0)),"") -> 300 | F42: =IFERROR(D42*E42,"") -> 300 | G42: 300 | H42: 300 | J42: 300 | L42: 300 | M42: MO principal (reconstruida)
B43: COSTO UNITARIO APU ESTÁNDAR | C43: Glb | F43: =F42 -> 300 | H43: 300 | J43: 300 | L43: 300 | M43: CU observados →
A45: 01.01.05 | B45: Guachimanía de obra, baños, vestidores de obra y otros provisionales | C45: Glb | D45: Cant/Rend | E45: P.Unit | F45: Subtotal | G45: Cant BF | H45: PU BF | I45: Cant PE | J45: PU PE | K45: Cant MF | L45: PU MF | M45: Observación
...

Sheet Resumen CU
A1: RESUMEN COMPARATIVO — COSTO UNITARIO POR APU
A2: 106 rubros · CU observado en cada obra vs. CU estándar propuesto
A4: Código | B4: Descripción | C4: Unidad | D4: CU BUENO FERRO | E4: CU PABLO ESPINOSA | F4: CU MUÑOZ FREILE | G4: CU ESTÁNDAR | H4: Cobertura | I4: Desv Max % | J4: Notas
A5: 01. PRELIMINARES
A6: 01.01.01 | B6: Replanteo Topográfico Ejes Estructurales y movimiento tierras | C6: Glb | D6: 0.73757645 | E6: 0.48171491 | F6: 0.1260928 | G6: ='APU Estándar'!F10 -> 160 | H6: 46084 | I6: 4.85 | J6: Tiene insumos con dispersión (ver hoja Reporte)
A7: 01.01.02 | B7: Replanteo Y Nivelación | C7: m2 | D7: 1.4155223 | E7: 1.1585613 | F7: 0.97282133 | G7: ='APU Estándar'!F32 -> 1.5074793 | H7: 46084 | I7: 0.46 | J7: Tiene insumos con dispersión (ver hoja Reporte)
A8: 01.01.03 | B8: Instalaciones eléctricas provisionales | C8: Glb | D8: 0.92197056 | E8: 1.2042873 | F8: 0.31523201 | G8: ='APU Estándar'!F38 -> 300 | H8: 0/3 | I8: 2.82
A9: 01.01.04 | B9: Instalaciones hidrosanitarias provisionales | C9: Glb | D9: 300 | E9: 300 | F9: 300 | G9: ='APU Estándar'!F43 -> 300 | H9: 0/3 | I9: 0
A10: 01.01.05 | B10: Guachimanía de obra, baños, vestidores de obra y otros provisionales | C10: Glb | D10: 3.0946341 | E10: 2.4544619 | F10: 0.93983156 | G10: ='APU Estándar'!F75 -> 1282.3635 | H10: 46084 | I10: 2.29 | J10: Tiene insumos con dispersión (ver hoja Reporte)
A11: 01.01.08 | B11: Cerramiento provisional de zaram y pingos | C11: ml | D11: 4.4366229 | E11: 3.5902645 | F11: 3.092476 | G11: ='APU Estándar'!F91 -> 26.061316 | H11: 46084 | I11: 0.43 | J11: Tiene insumos con dispersión (ver hoja Reporte)
A12: 01.01.09 | B12: Desmontaje de guachimanía de obra, baños, vestidores de obra y otros provisionales | C12: Glb | F12: 89.29 | G12: ='APU Estándar'!F96 -> 89.29 | H12: 46025 | J12: Cobertura única · Tiene insumos con dispersión (ver hoja Reporte)
A13: 02. MOVIMIENTOS DE TIERRA
A14: 02.01.01 | B14: Excavación mecánica en banco para conformación de plataforma | C14: m3 | E14: 1.25 | F14: 1.07 | G14: ='APU Estándar'!F103 -> 1.16 | H14: 46056 | I14: 0.17
A15: 02.01.02 | B15: Transporte desalojo de material a botadero | C15: m3 | E15: 36.78 | F15: 3.79 | G15: ='APU Estándar'!F109 -> 20.285 | H15: 46056 | I15: 8.7 | J15: Tiene insumos con dispersión (ver hoja Reporte)
A16: 02.01.03 | B16: Relleno compactado | C16: m3 | D16: 3 | E16: 3 | F16: 2.65 | G16: ='APU Estándar'!F115 -> 2.8833333 | H16: 46084 | I16: 0.13
A17: 02.01.04 | B17: Desbroce de Capa Vegetal | C17: m2 | D17: 0.65 | E17: 0.65 | F17: 0.58 | G17: ='APU Estándar'!F121 -> 0.62666667 | H17: 46084 | I17: 0.12
A18: 02.01.05 | B18: Rasanteo Y Conformación Manual De Plataformas | C18: m2 | D18: 0.7 | E18: 0.7 | F18: 0.74052312 | G18: ='APU Estándar'!F129 -> 0.74052312 | H18: 46084 | I18: 0.06 | J18: Tiene insumos con dispersión (ver hoja Reporte)
A19: 02.01.06 | B19: Transporte de material para relleno | C19: m3 | D19: 3.92 | G19: ='APU Estándar'!F135 -> 3.92 | H19: 46025 | J19: Cobertura única · Tiene insumos con dispersión (ver hoja Reporte)
A20: 02.01.07 | B20: Pruebas de compactación en plataformas | C20: Glb | D20: 350 | E20: 350 | F20: 500 | G20: ='APU Estándar'!F141 -> 400 | H20: 46084 | I20: 0.43
A21: 02.02.01 | B21: Excavaciones Y Relleno Compactado Para Instalaciones Hidrosanitarias | C21: ml | E21: 3.9 | F21: 3.9 | G21: ='APU Estándar'!F147 -> 3.9 | H21: 46056 | I21: 0
A22: 02.02.02 | B22: Excavaciones Y Relleno Compactado Para Instalaciones Eléctricas | C22: ml | E22: 3.9 | G22: ='APU Estándar'!F153 -> 3.9 | H22: 46025 | J22: Cobertura única · Tiene insumos con dispersión (ver hoja Reporte)
A23: 02.02.03 | B23: Cajas De Revisión H= 1,50x1,00x1,00m | C23: Und | G23: ='APU Estándar'!F157 -> 0 | H23: 0/3
A24: 02.02.04 | B24: Excavaciones Para Plintos Y Cimientos ( Maquina Y Perfilado Manual) | C24: m3 | D24: 14.251992 | E24: 7.5 | F24: 11.365149 | G24: ='APU Estándar'!F165 -> 12.641903 | H24: 46084 | I24: 0.9
A25: 02.02.05 | B25: Relleno Compactado Con Material Local (Plintos Y Cimientos) | C25: m3 | D25: 15.329419 | E25: 13.622624 | F25: 10.157457 | G25: ='APU Estándar'!F175 -> 13.076102 | H25: 46084 | I25: 0.51 | J25: Tiene insumos con dispersión (ver hoja Reporte)
A26: 02.02.06 | B26: Perfilado de taludes Muros (Incluye plástico polietileno) | C26: m2 | F26: 3.4999173 | G26: ='APU Estándar'!F187 -> 3.4203637 | H26: 46025 | J26: Cobertura única · Tiene insumos con dispersión (ver hoja Reporte)
A27: 03. ESTRUCTURA
A28: 03.01.01 | B28: Malla De Refuerzo 6*15 | C28: m2 | D28: 3.2280692 | E28: 3.0403732 | F28: 2.7852166 | G28: ='APU Estándar'!F200 -> 3.0490068 | H28: 46084 | I28: 0.16 | J28: Tiene insumos con dispersión (ver hoja Reporte)
A29: 03.01.02 | B29: Hierro 8 Mm X 12 M | C29: Kg. | D29: 1.3875105 | G29: ='APU Estándar'!F208 -> 1.3875105 | H29: 46025 | J29: Cobertura única · Tiene insumos con dispersión (ver hoja Reporte)
A30: 03.01.03 | B30: Hierro 10 Mm X 12 M | C30: Kg. | D30: 1.3946658 | E30: 1.1817746 | F30: 1.1264966 | G30: ='APU Estándar'!F223 -> 1.2456833 | H30: 46084 | I30: 0.24 | J30: Tiene insumos con dispersión (ver hoja Reporte)
A31: 03.01.04 | B31: Hierro 12 Mm X 12 M | C31: Kg. | D31: 1.552589 | E31: 1.469208 | F31: 1.8292711 | G31: ='APU Estándar'!F238 -> 1.6140944 | H31: 46084 | I31: 0.25 | J31: Tiene insumos con dispersión (ver hoja Reporte)
A32: 03.01.05 | B32: Hierro 14 Mm X 12 M | C32: Kg. | D32: 1.2175225 | E32: 1.2472578 | F32: 0.41154082 | G32: ='APU Estándar'!F250 -> 1.2229676 | H32: 46084 | I32: 2.03 | J32: Tiene insumos con dispersión (ver hoja Reporte)
A33: 03.01.06 | B33: Hierro 16 Mm X 12 M | C33: Kg. | D33: 1.414114 | E33: 1.5286974 | F33: 1.9208546 | G33: ='APU Estándar'!F263 -> 1.6492449 | H33: 46084 | I33: 0.36 | J33: Tiene insumos con dispersión (ver hoja Reporte)
A34: 03.01.07 | B34: Hierro 18 Mm X 12 M | C34: Kg. | E34: 1.4083458 | F34: 1.4240207 | G34: ='APU Estándar'!F271 -> 1.4161791 | H34: 46056 | I34: 0.01
A35: 03.02.01 | B35: Plástico Polietileno 2 Capas | C35: m2 | D35: 0.84771182 | E35: 0.80298195 | F35: 0.53723371 | G35: ='APU Estándar'!F283 -> 1.1723939 | H35: 46084 | I35: 0.58 | J35: Tiene insumos con dispersión (ver hoja Reporte)
A36: 03.02.02 | B36: Contrapiso De Hormigón Planta Baja F'c=210 Kg/Cm² | C36: m2 | D36: 17.060077 | E36: 19.16252 | F36: 17.817665 | G36: ='APU Estándar'!F314 -> 19.648491 | H36: 46084 | I36: 0.12 | J36: Tiene insumos con dispersión (ver hoja Reporte)
A37: 03.02.03 | B37: Juntas de dilatación en contrapiso | C37: m | E37: 7.0347518 | G37: ='APU Estándar'!F322 -> 6.7753546 | H37: 46025 | J37: Cobertura única · Tiene insumos con dispersión (ver hoja Reporte)
A38: 03.03.01 | B38: Hormigón En Replantillo F'c=180kg/Cm² | C38: m3 | D38: 82.378475 | E38: 57.001845 | F38: 29.869281 | G38: ='APU Estándar'!F332 -> 60.760626 | H38: 46084 | I38: 1.76 | J38: Tiene insumos con dispersión (ver hoja Reporte)
A39: 03.03.02 | B39: Hormigón En Plintos F'c=210kg/Cm² | C39: m3 | D39: 113.62364 | E39: 113.786 | F39: 112.79382 | G39: ='APU Estándar'!F343 -> 113.40115 | H39: 46084 | I39: 0.01
A40: 03.03.03 | B40: Hormigón En Cadenas F'c=210kg/Cm² | C40: m3 | D40: 117.59149 | E40: 34.417333 | F40: 112.10639 | G40: ='APU Estándar'!F355 -> 116.40575 | H40: 46084 | I40: 2.42 | J40: Tiene insumos con dispersión (ver hoja Reporte)
A41: 03.03.04 | B41: Hormigón En Muros F'c=210kg/Cm² | C41: m3 | D41: 133.15651 | F41: 114.09981 | G41: ='APU Estándar'!F372 -> 94.736132 | H41: 46056 | I41: 0.17 | J41: Tiene insumos con dispersión (ver hoja Reporte)
...

Sheet BD Materiales
A1: BASE DE DATOS — MATERIALES
A2: Edite la columna D (PU ESTÁNDAR) — los APUs y el CU se recalculan automáticamente
A4: Código | B4: Descripción | C4: Unidad | D4: PU ESTÁNDAR | E4: PU BUENO FERRO | F4: PU PABLO ESPINOSA | G4: PU MUÑOZ FREILE | H4: Usos | I4: Método | J4: Observación
A5: MAT-0001 | B5: Aceite Havoline | C5: Uni. | D5: 6.25 | F5: 6.25 | H5: 1 | I5: único | J5: Cobertura única
A6: MAT-0002 | B6: Aceite Multiuso 3 en 1 | C6: Uni. | D6: 1.18 | G6: 1.18 | H6: 1 | I6: único | J6: Cobertura única
A7: MAT-0003 | B7: Adoquin Toledo 6cm Color 16X16 | C7: ml | D7: 15.56 | F7: 15.56 | H7: 2 | I7: promedio
A8: MAT-0004 | B8: Adoquin Toledo 6cm Color 16X24 (Adoquin Toledo 6cm Color 24X24) | C8: ml | D8: 15.56 | F8: 15.56 | H8: 2 | I8: promedio
A9: MAT-0005 | B9: Adoquin Toledo 6cm Color 24X24 | C9: ml | D9: 15.56 | F9: 15.56 | H9: 2 | I9: promedio
A10: MAT-0006 | B10: Alambre galvanizado N 14 | C10: rollo | D10: 82.9725 | E10: 82.9725 | H10: 4 | I10: promedio
A11: MAT-0007 | B11: Alambre galvanizado Nº 14 | C11: R-Alambre | D11: 96.23 | F11: 96.23 | H11: 1 | I11: único | J11: Cobertura única
A12: MAT-0008 | B12: Alambre galvanizado Nº 14 | C12: rollo | D12: 92.45 | F12: 92.45 | H12: 1 | I12: único | J12: Cobertura única
A13: MAT-0009 | B13: Alambre recocido N.18 (20kg) (Alambre recocido N.18 (20kg)) | C13: R-Alambre | D13: 31.17 | G13: 31.17 | H13: 1 | I13: promedio
A14: MAT-0010 | B14: Alambre recocido N.18 (20kg) (Alambre recocido N.18 (20kg)) | C14: rollo | D14: 31.8 | G14: 31.8 | H14: 1 | I14: único | J14: Cobertura única
A15: MAT-0011 | B15: Alambre recocido N18 (20kg) (Alambre recocido N18 (20kg)) | C15: Rr20Kg | D15: 32.625 | E15: 29.145 | F15: 34.495 | G15: 34.235 | H15: 4 | I15: promedio
A16: MAT-0012 | B16: Aldaba Galvanizada 2'' | C16: Uni. | D16: 0.675 | E16: 0.32 | F16: 1.03 | H16: 1 | I16: mediana | J16: Criterio pendiente — desv 222%
A17: MAT-0013 | B17: Alfombra atrapamugre | C17: m2 | D17: 17.32 | G17: 17.32 | H17: 1 | I17: único | J17: Cobertura única
A18: MAT-0014 | B18: Amoladora 9" DWE496-B3 Dewalt | C18: Uni. | D18: 137.955 | F18: 134.16 | G18: 141.75 | H18: 1 | I18: promedio
A19: MAT-0015 | B19: Arena Fina | D19: 9.43 | E19: 6.59 | G19: 12.27 | H19: 1 | I19: promedio
A20: MAT-0016 | B20: Arena Fina | C20: m3 | D20: 13.481309 | F20: 16.309593 | G20: 12.538547 | H20: 4 | I20: promedio
A21: MAT-0017 | B21: Arena Rosada | C21: m3 | D21: 13.250168 | E21: 13.116667 | F21: 12.163423 | G21: 13.866667 | H21: 12 | I21: promedio
A22: MAT-0018 | B22: Armellas (Par de Armellas) | C22: Uni. | D22: 0.55 | F22: 0.53 | G22: 0.57 | H22: 1 | I22: promedio
A23: MAT-0019 | B23: Balde de construccion caucho | C23: Uni. | D23: 1.5633333 | E23: 1.38 | F23: 1.39 | G23: 1.92 | H23: 1 | I23: promedio
A24: MAT-0020 | B24: Barra agricola de 14 libras | C24: Uni. | D24: 17.085 | F24: 16.95 | G24: 17.22 | H24: 1 | I24: promedio
A25: MAT-0021 | B25: Bisagra Negra 3" | C25: Uni. | D25: 0.61 | E25: 0.48 | F25: 0.74 | H25: 1 | I25: promedio
A26: MAT-0022 | B26: Bloque alivianado 10x20x40 | C26: Uni. | D26: 0.33433333 | E26: 0.34 | F26: 0.33 | G26: 0.333 | H26: 1 | I26: promedio
A27: MAT-0023 | B27: Bloque alivianado 15x20x40 | C27: Uni. | D27: 0.346 | E27: 0.35 | F27: 0.34 | G27: 0.344 | H27: 2 | I27: promedio
A28: MAT-0024 | B28: Bloque alivianado 20x40x20 | C28: Uni. | D28: 0.4434125 | E28: 0.4539 | F28: 0.42 | G28: 0.449875 | H28: 2 | I28: promedio
A29: MAT-0025 | B29: Bondex Plus 25kg | C29: Uni. | D29: 6.63 | E29: 6.63 | H29: 2 | I29: promedio
A30: MAT-0026 | B30: Bondex Premium 25kg | C30: Uni. | D30: 11.4725 | F30: 11.4725 | H30: 1 | I30: único | J30: Cobertura única
A31: MAT-0027 | B31: Bondex Standar 25Kg | C31: Uni. | D31: 4.17 | G31: 4.17 | H31: 1 | I31: único | J31: Cobertura única
A32: MAT-0028 | B32: Bordillo 100X25X8 Gris Natural | C32: ml | D32: 6.79 | F32: 6.79 | H32: 1 | I32: único | J32: Cobertura única
A33: MAT-0029 | B33: Broca Concreto 1/2" 12mm | C33: Uni. | D33: 4.57 | G33: 4.57 | H33: 1 | I33: único | J33: Cobertura única
A34: MAT-0030 | B34: Broca Concreto 1/2" 13mm | C34: Uni. | D34: 1.505 | F34: 1.505 | H34: 2 | I34: promedio
A35: MAT-0031 | B35: Broca Concreto 1/2X12cm | C35: Uni. | D35: 4.25 | E35: 4.25 | H35: 1 | I35: único | J35: Cobertura única
A36: MAT-0032 | B36: Broca Concreto 1/2X30cm | C36: Uni. | D36: 5.1 | E36: 5.0825 | G36: 3.495 | H36: 4 | I36: mediana | J36: Criterio pendiente — desv 170%
A37: MAT-0033 | B37: Broca Concreto 5/8X12cm | C37: Uni. | D37: 5.053 | E37: 5.053 | H37: 1 | I37: único | J37: Cobertura única
A38: MAT-0034 | B38: Broca Madera Titanio3/8" | C38: Uni. | D38: 1.02 | G38: 1.02 | H38: 2 | I38: promedio
A39: MAT-0035 | B39: Broca Metal Cobalto 5/32" | C39: Uni. | D39: 1.61 | G39: 1.61 | H39: 1 | I39: único | J39: Cobertura única
A40: MAT-0036 | B40: Brocha 3" | C40: Uni. | D40: 1.07 | F40: 1.07 | H40: 1 | I40: único | J40: Cobertura única
A41: MAT-0037 | B41: Brocha 3" | C41: Uni. | D41: 2.01 | F41: 2.01 | H41: 1 | I41: único | J41: Cobertura única
...

Sheet BD Mano de Obra
A1: BASE DE DATOS — MANO DE OBRA
A2: Edite la columna D (PU ESTÁNDAR) — los APUs y el CU se recalculan automáticamente
A4: Código | B4: Descripción | C4: Unidad | D4: PU ESTÁNDAR | E4: PU BUENO FERRO | F4: PU PABLO ESPINOSA | G4: PU MUÑOZ FREILE | H4: Usos | I4: Método | J4: Observación
A5: MO-0001 | B5: Guachimanía de obra | C5: mes | D5: 172.5 | E5: 172.5 | H5: 1 | I5: único | J5: Cobertura única
A6: MO-0002 | B6: M, Plástico Negro Para Protección De Terminados | C6: m2 | D6: 0.36 | F6: 0.36 | H6: 1 | I6: único | J6: Cobertura única
A7: MO-0003 | B7: M. Acceso Peatonal (Obra Civil) | C7: m2 | D7: 7 | E7: 7 | G7: 7 | H7: 1 | I7: promedio
A8: MO-0004 | B8: M. Adoquín En Acceso Peatonal | C8: m2 | D8: 2.8 | F8: 2.8 | H8: 1 | I8: único | J8: Cobertura única
A9: MO-0005 | B9: M. Adoquín En Estacionamiento | C9: m2 | D9: 2.8 | F9: 2.8 | H9: 1 | I9: único | J9: Cobertura única
A10: MO-0006 | B10: M. Alfeizar En Antepecho | C10: ml | D10: 2.8 | F10: 2.8 | H10: 1 | I10: único | J10: Cobertura única
A11: MO-0007 | B11: M. Alfeizar En Ventana | C11: ml | D11: 9.45 | E11: 9.45 | F11: 9.45 | H11: 1 | I11: promedio
A12: MO-0008 | B12: M. Apuntalamiento de losa deck metálico | C12: m2 | D12: 1.54 | E12: 1.9 | F12: 1.36 | G12: 1.36 | H12: 1 | I12: promedio
A13: MO-0009 | B13: M. Arrostramiento Vertical de Mampostería | C13: ml | D13: 6.37 | E13: 6.37 | F13: 6.37 | H13: 1 | I13: promedio
A14: MO-0010 | B14: M. Bordillo De Terrazas | C14: ml | D14: 6.38 | E14: 6.38 | F14: 6.38 | G14: 6.38 | H14: 1 | I14: promedio
A15: MO-0011 | B15: M. Bordillo en estacionamiento (1,00x0,10x0,30m) | C15: ml | D15: 2.6 | F15: 2.6 | H15: 1 | I15: único | J15: Cobertura única
A16: MO-0012 | B16: M. Canal recolector aguas lluvias | C16: ml | D16: 15.8 | E16: 15.8 | F16: 15.8 | H16: 1 | I16: promedio
A17: MO-0013 | B17: M. Cerramiento provisional de zaram y pingos | C17: ml | D17: 2.14 | E17: 2.14 | F17: 2.14 | G17: 2.14 | H17: 1 | I17: promedio
A18: MO-0014 | B18: M. Conformación plataforma - Acceso Peatonal | C18: m2 | D18: 0.7 | E18: 0.7 | F18: 0.7 | G18: 0.7 | H18: 1 | I18: promedio
A19: MO-0015 | B19: M. Contrapiso De Hormigón Planta Baja F'c=210 Kg/Cm² | C19: m2 | D19: 7 | E19: 8 | F19: 6.5 | G19: 6.5 | H19: 1 | I19: promedio
A20: MO-0016 | B20: M. Desmontaje de guachimanía de obra, baños, vestidores de obra y otros provisionales | C20: Glb | D20: 89.29 | G20: 89.29 | H20: 1 | I20: único | J20: Cobertura única
A21: MO-0017 | B21: M. Dinteles De Hormigón F'c = 180 Kg/Cm2 | C21: m | D21: 6.370016 | E21: 6.37 | F21: 6.3700481 | G21: 6.37 | H21: 1 | I21: promedio
A22: MO-0018 | B22: M. Ducha Rehundida | C22: m2 | D22: 13.26 | E22: 13.26 | F22: 13.26 | G22: 13.26 | H22: 1 | I22: promedio
A23: MO-0019 | B23: M. Encofrado de gradas exteriores (Detalle para luces acceso peatonal) | C23: m2 | D23: 6.16 | E23: 6.16 | H23: 1 | I23: único | J23: Cobertura única
A24: MO-0020 | B24: M. Encofrado y Desencofrado Columnas Circulares | C24: m2 | D24: 25.09 | E24: 25.09 | H24: 1 | I24: único | J24: Cobertura única
A25: MO-0021 | B25: M. Encofrado y Desencofrado Columnas Rectangulares | C25: m2 | D25: 11.25 | E25: 13.89 | F25: 9.93 | G25: 9.93 | H25: 1 | I25: promedio
A26: MO-0022 | B26: M. Encofrado y Desencofrado Dintel Descolgado Perimetral | C26: ml | D26: 6.5 | E26: 6.5 | F26: 6.5 | G26: 6.5 | H26: 1 | I26: promedio
A27: MO-0023 | B27: M. Encofrado y Desencofrado Losa Perimetral | C27: ml | D27: 3.87 | E27: 3.85 | F27: 3.88 | G27: 3.88 | H27: 1 | I27: promedio
A28: MO-0024 | B28: M. Encofrado y Desencofrado Muros | C28: m2 | D28: 11.285 | E28: 12.77 | G28: 9.8 | H28: 1 | I28: promedio
A29: MO-0025 | B29: M. Encofrado y Desencofrado de Losa | C29: m2 | D29: 12.565 | E29: 13.63 | F29: 11.5 | H29: 1 | I29: promedio
A30: MO-0026 | B30: M. Encofrado y Desencofrado de Vigas | C30: m2 | D30: 11.5 | E30: 25.87 | F30: 11 | G30: 11.5 | H30: 1 | I30: mediana | J30: Criterio pendiente — desv 135%
A31: MO-0027 | B31: M. Enlucido De Fachada | C31: m2 | D31: 7.4633333 | E31: 7.99 | F31: 6.8 | G31: 7.6 | H31: 1 | I31: promedio
A32: MO-0028 | B32: M. Enlucido De Fajas Exteriores | C32: ml | D32: 3.25 | E32: 3.4 | F32: 3.1 | H32: 1 | I32: promedio
A33: MO-0029 | B33: M. Enlucido De Fajas Interiores | C33: ml | D33: 3 | E33: 3.1 | F33: 2.9 | H33: 1 | I33: promedio
A34: MO-0030 | B34: M. Enlucido De Filos Exteriores | C34: m2 | D34: 1.25 | E34: 1.4 | F34: 1.1 | H34: 1 | I34: promedio
A35: MO-0031 | B35: M. Enlucido De Filos Interiores | C35: ml | D35: 1.45 | E35: 1.6 | F35: 1.3 | H35: 1 | I35: promedio
A36: MO-0032 | B36: M. Enlucido Exterior Terminado Hormigón Visto | C36: m2 | D36: 3.95 | F36: 3.1 | G36: 4.8 | H36: 1 | I36: promedio
A37: MO-0033 | B37: M. Enlucido Vertical Interior | C37: m2 | D37: 4.89 | E37: 5.02 | F37: 4.8 | G37: 4.85 | H37: 1 | I37: promedio
A38: MO-0034 | B38: M. Excavaciones Para Plintos Y Cimientos ( Maquina Y Perfilado Manual) | C38: m3 | D38: 7.8333333 | E38: 7.5 | F38: 7.5 | G38: 8.5 | H38: 1 | I38: promedio
A39: MO-0035 | B39: M. Excavaciones Y Relleno Compactado Para Instalaciones Eléctricas | C39: ml | D39: 3.9 | F39: 3.9 | H39: 1 | I39: único | J39: Cobertura única
A40: MO-0036 | B40: M. Excavaciones Y Relleno Compactado Para Instalaciones Hidrosanitarias | C40: ml | D40: 3.9 | F40: 3.9 | G40: 3.9 | H40: 1 | I40: promedio
A41: MO-0037 | B41: M. Forrado de columnas metálicas | C41: m2 | D41: 3.8 | F41: 3.8 | G41: 3.8 | H41: 1 | I41: promedio
...

Sheet BD Equipo
A1: BASE DE DATOS — EQUIPO
A2: Edite la columna D (PU ESTÁNDAR) — los APUs y el CU se recalculan automáticamente
A4: Código | B4: Descripción | C4: Unidad | D4: PU ESTÁNDAR | E4: PU BUENO FERRO | F4: PU PABLO ESPINOSA | G4: PU MUÑOZ FREILE | H4: Usos | I4: Método | J4: Observación
A5: EQ-0001 | B5: Alquiler Andamio | C5: Uni. | D5: 0.35957143 | E5: 0.35871429 | F5: 0.36 | G5: 0.36 | H5: 12 | I5: promedio
A6: EQ-0002 | B6: Alquiler Generador | C6: día | D6: 44.64 | G6: 44.64 | H6: 1 | I6: único | J6: Cobertura única
A7: EQ-0003 | B7: Alquiler Puntales | C7: Uni. | D7: 0.05 | G7: 0.05 | H7: 1 | I7: único | J7: Cobertura única
A8: EQ-0004 | B8: Alquiler Rodillo | C8: Dia | D8: 89.29 | G8: 89.29 | H8: 1 | I8: único | J8: Cobertura única
A9: EQ-0005 | B9: Alquiler Rotomartillo | C9: Uni. | D9: 31.25 | E9: 31.25 | G9: 31.25 | H9: 4 | I9: promedio
A10: EQ-0006 | B10: Alquiler andamio | C10: Uni. | D10: 0.36 | F10: 0.36 | H10: 3 | I10: promedio
A11: EQ-0007 | B11: Alquiler compactador sapo | C11: Uni. | D11: 25 | F11: 25 | G11: 25 | H11: 3 | I11: promedio
A12: EQ-0008 | B12: Alquiler compactador sapo | C12: día | D12: 25 | E12: 25 | F12: 25 | G12: 25 | H12: 1 | I12: promedio
A13: EQ-0009 | B13: Alquiler concretera | C13: día | D13: 31.25 | F13: 31.25 | G13: 31.25 | H13: 1 | I13: promedio
A14: EQ-0010 | B14: Alquiler de Elevador a gasolina | C14: día | D14: 35.71 | G14: 35.71 | H14: 1 | I14: único | J14: Cobertura única
A15: EQ-0011 | B15: Alquiler de Maquinaria (retroex (Alquiler de Maquinaria (retroexcavadora)) | C15: Hr, | D15: 22 | G15: 22 | H15: 1 | I15: único | J15: Cobertura única
A16: EQ-0012 | B16: Alquiler de Maquinaria (retroex (Alquiler de Maquinaria (retroexcavadora)) | C16: Hr. | D16: 22 | E16: 22 | G16: 22 | H16: 4 | I16: promedio
A17: EQ-0013 | B17: Alquiler de Tableros de madera | C17: Uni. | D17: 0.0892 | E17: 0.0892 | H17: 1 | I17: único | J17: Cobertura única
A18: EQ-0014 | B18: Alquiler de Tablones | C18: Uni. | D18: 0.089948261 | E18: 0.089801667 | F18: 0.09 | G18: 0.09 | H18: 14 | I18: promedio
A19: EQ-0015 | B19: Alquiler vibrador | C19: Uni. | D19: 17.86 | E19: 17.86 | F19: 17.86 | G19: 17.86 | H19: 9 | I19: promedio
A20: EQ-0016 | B20: Arnes de Seguridad + cuerda 3P. (Arnes de Seguridad + 3P Fijacion total) | C20: Uni. | D20: 49.88 | G20: 49.88 | H20: 1 | I20: único | J20: Cobertura única
A21: EQ-0017 | B21: Bomba Estacionaria | C21: m3 | D21: 8 | E21: 8 | F21: 8 | G21: 8 | H21: 10 | I21: promedio
A22: EQ-0018 | B22: Casco | C22: Uni. | D22: 4.13 | E22: 9.52 | F22: 4.13 | G22: 4.12 | H22: 1 | I22: mediana | J22: Criterio pendiente — desv 131%
A23: EQ-0019 | B23: Cinta amarilla Precaución 200MT | C23: mts. | D23: 0.0217 | E23: 0.0164 | F23: 0.0222 | G23: 0.0265 | H23: 1 | I23: promedio
A24: EQ-0020 | B24: Gafa Transparente Reforzada | C24: Uni. | D24: 1.15 | F24: 1.82 | G24: 0.48 | H24: 1 | I24: mediana | J24: Criterio pendiente — desv 279%
A25: EQ-0021 | B25: Guante de Cuero Operador | C25: Uni. | D25: 1.4566667 | E25: 1.43 | F25: 1.47 | G25: 1.47 | H25: 1 | I25: promedio
A26: EQ-0022 | B26: Guantes de Caucho | C26: pr | D26: 1.22 | F26: 1.16 | G26: 1.28 | H26: 1 | I26: promedio
A27: EQ-0023 | B27: Horas Maquinas Mini Cargadora | C27: Hr. | D27: 22.5 | E27: 20 | G27: 25 | H27: 1 | I27: promedio
A28: EQ-0024 | B28: Horas Maquinas Retroexcavadora | C28: Hr. | D28: 22.42875 | E28: 23.143333 | F28: 22 | G28: 22 | H28: 3 | I28: promedio
A29: EQ-0025 | B29: M. Desbroce de Capa Vegetal | C29: m2 | D29: 0.62666667 | E29: 0.65 | F29: 0.65 | G29: 0.58 | H29: 1 | I29: promedio
A30: EQ-0026 | B30: M. Excavación mecánica en banco para conformación de plataforma | C30: m3 | D30: 1.16 | F30: 1.25 | G30: 1.07 | H30: 1 | I30: promedio
A31: EQ-0027 | B31: M. Pruebas De Laboratorio | C31: Glb | D31: 60 | E31: 60 | F31: 40 | G31: 80 | H31: 1 | I31: promedio
A32: EQ-0028 | B32: M. Pruebas de compactación en plataformas | C32: Glb | D32: 400 | E32: 350 | F32: 350 | G32: 500 | H32: 1 | I32: promedio
A33: EQ-0029 | B33: M. Transporte de material para relleno | C33: m3 | D33: 3.92 | E33: 3.92 | H33: 1 | I33: único | J33: Cobertura única
A34: EQ-0030 | B34: M. Transporte desalojo de material a botadero | C34: m3 | D34: 20.285 | F34: 36.78 | G34: 3.79 | H34: 1 | I34: mediana (outlier detectado) | J34: Revisar — desv 870%
A35: EQ-0031 | B35: Mantenimiento Herramientas | C35: Glb | D35: 28.28 | E35: 24.77 | G35: 31.79 | H35: 1 | I35: promedio
A36: EQ-0032 | B36: Mascara Para Esmerilar Reforzad (ascara Para Esmerilar Reforzada) | C36: Uni. | D36: 4.13 | F36: 4.13 | H36: 1 | I36: único | J36: Cobertura única
A37: EQ-0033 | B37: Servicio mínimo de Bombeo | C37: m3 | D37: 8 | E37: 8 | H37: 3 | I37: promedio
A38: EQ-0034 | B38: Trans. Desalojo-Escombro Botade (Trans. Desalojo-Escombro Botadero fuera de obra) | C38: viaje | D38: 35 | G38: 35 | H38: 2 | I38: promedio
A39: EQ-0035 | B39: Transporte Adoquin | C39: Uni. | D39: 35 | F39: 35 | H39: 2 | I39: promedio
A40: EQ-0036 | B40: Transporte Limpieza Y Desalojo De Escombros + tickets emgirs | C40: Viaje | D40: 36.43 | E40: 39.29 | F40: 35 | G40: 35 | H40: 1 | I40: promedio
A41: EQ-0037 | B41: Transporte de Montacargas | C41: Uni. | D41: 70 | G41: 70 | H41: 1 | I41: único | J41: Cobertura única
...

Sheet BD Rendimientos
A1: BASE DE DATOS — RENDIMIENTOS (Cantidad de insumo por unidad de obra) | L1: Clave única
A2: Edite la columna G (RENDIMIENTO) — los APUs se recalculan automáticamente
A4: APU Código | B4: APU Descripción | C4: APU Unid. | D4: Sección | E4: Insumo | F4: Unid. | G4: RENDIMIENTO | H4: Cant BF | I4: Cant PE | J4: Cant MF | K4: Observación
A5: 01.01.01 | B5: Replanteo Topográfico Ejes Estructurales y movimiento tierras | C5: Glb | D5: MO | E5: M. Replanteo Topográfico Ejes Estructurales y movimiento tierras | F5: Glb | G5: 1 | H5: 1 | I5: 1 | J5: 1 | K5: MO principal (rend=1) | L5: 01.01.01|M. Replanteo Topográfico Ejes Estructurales y movimiento tierras|Glb|mano_obra
A6: 01.01.02 | B6: Replanteo Y Nivelación | C6: m2 | D6: MAT | E6: Alambre galvanizado N 14 | F6: rollo | G6: 0.0030732352 | H6: 1 | K6: cobertura única | L6: 01.01.02|Alambre galvanizado N 14|rollo|materiales
A7: 01.01.02 | B7: Replanteo Y Nivelación | C7: m2 | D7: MAT | E7: Broca Madera Titanio3/8" | F7: Uni. | G7: 0.0010507734 | J7: 1 | K7: cobertura única | L7: 01.01.02|Broca Madera Titanio3/8"|Uni.|materiales
A8: 01.01.02 | B8: Replanteo Y Nivelación | C8: m2 | D8: MAT | E8: Caoba Roja | F8: lb | G8: 0.017743166 | H8: 19.5 | I8: 4.42 | J8: 8.11 | K8: Rendimiento disperso | L8: 01.01.02|Caoba Roja|lb|materiales
A9: 01.01.02 | B9: Replanteo Y Nivelación | C9: m2 | D9: MAT | E9: Cementina | F9: saco | G9: 0.024467622 | H9: 7 | I9: 9 | J9: 15 | L9: 01.01.02|Cementina|saco|materiales
A10: 01.01.02 | B10: Replanteo Y Nivelación | C10: m2 | D10: MAT | E10: Clavos de acero 2'' | F10: Kg. | G10: 0.0046098528 | H10: 1.5 | K10: cobertura única | L10: 01.01.02|Clavos de acero 2''|Kg.|materiales
A11: 01.01.02 | B11: Replanteo Y Nivelación | C11: m2 | D11: MAT | E11: Clavos de acero 21/2'' | F11: Kg. | G11: 0.0040142909 | H11: 2 | I11: 1 | J11: 0.5 | K11: Rendimiento disperso | L11: 01.01.02|Clavos de acero 21/2''|Kg.|materiales
A12: 01.01.02 | B12: Replanteo Y Nivelación | C12: m2 | D12: MAT | E12: Clavos galvanizados 2'' | F12: Kg. | G12: 0.0093924525 | H12: 3.5 | I12: 2 | L12: 01.01.02|Clavos galvanizados 2''|Kg.|materiales
A13: 01.01.02 | B13: Replanteo Y Nivelación | C13: m2 | D13: MAT | E13: Clavos galvanizados 2 1/2'' | F13: Kg. | G13: 0.0062778171 | H13: 4 | J13: 0.25 | K13: Rendimiento disperso | L13: 01.01.02|Clavos galvanizados 2 1/2''|Kg.|materiales
A14: 01.01.02 | B14: Replanteo Y Nivelación | C14: m2 | D14: MAT | E14: Clavos galvanizados 3" | F14: Kg. | G14: 0.0040142909 | I14: 1 | K14: cobertura única | L14: 01.01.02|Clavos galvanizados 3"|Kg.|materiales
A15: 01.01.02 | B15: Replanteo Y Nivelación | C15: m2 | D15: MAT | E15: Cuartón 6 x 4 de eucalipto | F15: Uni. | G15: 0.013660054 | J15: 13 | K15: cobertura única | L15: 01.01.02|Cuartón 6 x 4 de eucalipto|Uni.|materiales
A16: 01.01.02 | B16: Replanteo Y Nivelación | C16: m2 | D16: MAT | E16: Manguera transparente | F16: ml | G16: 0.10035727 | I16: 25 | K16: cobertura única | L16: 01.01.02|Manguera transparente|ml|materiales
A17: 01.01.02 | B17: Replanteo Y Nivelación | C17: m2 | D17: MAT | E17: Pingos de 2.5 mts | F17: Uni. | G17: 0.040142909 | H17: 19 | I17: 10 | J17: 3 | K17: Rendimiento disperso | L17: 01.01.02|Pingos de 2.5 mts|Uni.|materiales
A18: 01.01.02 | B18: Replanteo Y Nivelación | C18: m2 | D18: MAT | E18: Pingos de 3 mts | F18: Uni. | G18: 0.022698388 | I18: 10 | J18: 5 | K18: Rendimiento disperso | L18: 01.01.02|Pingos de 3 mts|Uni.|materiales
A19: 01.01.02 | B19: Replanteo Y Nivelación | C19: m2 | D19: MAT | E19: Riel de eucalipto | F19: Uni. | G19: 0.069243217 | H19: 32 | I19: 10 | L19: 01.01.02|Riel de eucalipto|Uni.|materiales
A20: 01.01.02 | B20: Replanteo Y Nivelación | C20: m2 | D20: MAT | E20: Spray Rojo | F20: Uni. | G20: 0.0092197056 | H20: 3 | I20: 5 | J20: 2 | K20: Rendimiento disperso | L20: 01.01.02|Spray Rojo|Uni.|materiales
A21: 01.01.02 | B21: Replanteo Y Nivelación | C21: m2 | D21: MAT | E21: Tablas de Monte | F21: Uni. | G21: 0.030827778 | H21: 7 | I21: 10 | L21: 01.01.02|Tablas de Monte|Uni.|materiales
A22: 01.01.02 | B22: Replanteo Y Nivelación | C22: m2 | D22: MO | E22: M. Replanteo Y Nivelación | F22: m2 | G22: 1 | H22: 325.39 | I22: 249.11 | J22: 951.68 | K22: MO principal (rend=1) | L22: 01.01.02|M. Replanteo Y Nivelación|m2|mano_obra
A23: 01.01.05 | B23: Guachimanía de obra, baños, vestidores de obra y otros provisionales | C23: Glb | D23: MAT | E23: Alambre galvanizado N 14 | F23: rollo | G23: 1 | H23: 1 | K23: cobertura única | L23: 01.01.05|Alambre galvanizado N 14|rollo|materiales
A24: 01.01.05 | B24: Guachimanía de obra, baños, vestidores de obra y otros provisionales | C24: Glb | D24: MAT | E24: Aldaba Galvanizada 2'' | F24: Uni. | G24: 1.5 | H24: 1 | I24: 2 | L24: 01.01.05|Aldaba Galvanizada 2''|Uni.|materiales
A25: 01.01.05 | B25: Guachimanía de obra, baños, vestidores de obra y otros provisionales | C25: Glb | D25: MAT | E25: Armellas (Par de Armellas) | F25: Uni. | G25: 3 | I25: 2 | J25: 4 | L25: 01.01.05|Armellas (Par de Armellas)|Uni.|materiales
A26: 01.01.05 | B26: Guachimanía de obra, baños, vestidores de obra y otros provisionales | C26: Glb | D26: MAT | E26: Bisagra Negra 3" | F26: Uni. | G26: 6 | H26: 6 | I26: 6 | L26: 01.01.05|Bisagra Negra 3"|Uni.|materiales
A27: 01.01.05 | B27: Guachimanía de obra, baños, vestidores de obra y otros provisionales | C27: Glb | D27: MAT | E27: Bloque alivianado 15x20x40 | F27: Uni. | G27: 700 | H27: 700 | K27: cobertura única | L27: 01.01.05|Bloque alivianado 15x20x40|Uni.|materiales
A28: 01.01.05 | B28: Guachimanía de obra, baños, vestidores de obra y otros provisionales | C28: Glb | D28: MAT | E28: Candado Viro Fai Anticizalla 70 | F28: Uni. | G28: 1 | J28: 1 | K28: cobertura única | L28: 01.01.05|Candado Viro Fai Anticizalla 70|Uni.|materiales
A29: 01.01.05 | B29: Guachimanía de obra, baños, vestidores de obra y otros provisionales | C29: Glb | D29: MAT | E29: Cemento Campeón | F29: saco | G29: 3 | H29: 12 | I29: 3 | J29: 1 | K29: Rendimiento disperso | L29: 01.01.05|Cemento Campeón|saco|materiales
A30: 01.01.05 | B30: Guachimanía de obra, baños, vestidores de obra y otros provisionales | C30: Glb | D30: MAT | E30: Clavos de acero 2.1/2” (Clavos de acero 2.1/2” (1 kilo)) | F30: Kg. | G30: 0.5 | J30: 0.5 | K30: cobertura única | L30: 01.01.05|Clavos de acero 2.1/2” (Clavos de acero 2.1/2” (1 kilo))|Kg.|materiales
A31: 01.01.05 | B31: Guachimanía de obra, baños, vestidores de obra y otros provisionales | C31: Glb | D31: MAT | E31: Clavos galvanizados 2'' | F31: Kg. | G31: 2.3333333 | H31: 2.5 | I31: 1.5 | J31: 3 | L31: 01.01.05|Clavos galvanizados 2''|Kg.|materiales
A32: 01.01.05 | B32: Guachimanía de obra, baños, vestidores de obra y otros provisionales | C32: Glb | D32: MAT | E32: Clavos galvanizados 2 1/2'' | F32: Kg. | G32: 2.25 | H32: 2.5 | J32: 2 | L32: 01.01.05|Clavos galvanizados 2 1/2''|Kg.|materiales
A33: 01.01.05 | B33: Guachimanía de obra, baños, vestidores de obra y otros provisionales | C33: Glb | D33: MAT | E33: Clavos Zinc 2 1/2"x9 (Caja 20kg (Clavos Zinc 2 1/2"x9 (Caja 20kg)) | F33: Kg. | G33: 1.25 | I33: 0.5 | J33: 2 | K33: Rendimiento disperso | L33: 01.01.05|Clavos Zinc 2 1/2"x9 (Caja 20kg (Clavos Zinc 2 1/2"x9 (Caja 20kg))|Kg.|materiales
A34: 01.01.05 | B34: Guachimanía de obra, baños, vestidores de obra y otros provisionales | C34: Glb | D34: MAT | E34: Cuartón 6 x 4 de eucalipto | F34: Uni. | G34: 54 | J34: 54 | K34: cobertura única | L34: 01.01.05|Cuartón 6 x 4 de eucalipto|Uni.|materiales
A35: 01.01.05 | B35: Guachimanía de obra, baños, vestidores de obra y otros provisionales | C35: Glb | D35: MAT | E35: Disco diamante segmentado 9" | F35: Uni. | G35: 1 | H35: 1 | K35: cobertura única | L35: 01.01.05|Disco diamante segmentado 9"|Uni.|materiales
A36: 01.01.05 | B36: Guachimanía de obra, baños, vestidores de obra y otros provisionales | C36: Glb | D36: MAT | E36: Inodoro Guachimania | F36: Uni. | G36: 1 | I36: 1 | J36: 1 | L36: 01.01.05|Inodoro Guachimania|Uni.|materiales
A37: 01.01.05 | B37: Guachimanía de obra, baños, vestidores de obra y otros provisionales | C37: Glb | D37: MAT | E37: Lavabo Guachimania | F37: Uni. | G37: 1 | I37: 1 | J37: 1 | L37: 01.01.05|Lavabo Guachimania|Uni.|materiales
A38: 01.01.05 | B38: Guachimanía de obra, baños, vestidores de obra y otros provisionales | C38: Glb | D38: MAT | E38: Pingos de 2.5 mts | F38: Uni. | G38: 8.5 | I38: 6 | J38: 11 | L38: 01.01.05|Pingos de 2.5 mts|Uni.|materiales
A39: 01.01.05 | B39: Guachimanía de obra, baños, vestidores de obra y otros provisionales | C39: Glb | D39: MAT | E39: Pingos de 3 mts. | F39: Uni. | G39: 24 | J39: 24 | K39: cobertura única | L39: 01.01.05|Pingos de 3 mts.|Uni.|materiales
A40: 01.01.05 | B40: Guachimanía de obra, baños, vestidores de obra y otros provisionales | C40: Glb | D40: MAT | E40: Pingos de 4 mts. | F40: Uni. | G40: 4.5 | H40: 5 | J40: 4 | L40: 01.01.05|Pingos de 4 mts.|Uni.|materiales
A41: 01.01.05 | B41: Guachimanía de obra, baños, vestidores de obra y otros provisionales | C41: Glb | D41: MAT | E41: Pingos de 6 mts. | F41: Uni. | G41: 8.6666667 | H41: 10 | I41: 4 | J41: 12 | L41: 01.01.05|Pingos de 6 mts.|Uni.|materiales
...

Sheet Historial Conversación
A4: # | B4: Actor / Fase | C4: Contenido
A5: 1 | B5: 👤 Usuario | C5: Analiza este archivo que es un análisis de precios unitarios.
A6: 2 | B6: 🤖 Claude — Análisis inicial | C6: Revisé la estructura del archivo "006. Cuadro Comparativo APUs": • 2,263 filas · 17 encabezados de capítulo · 106 APUs • 3 columnas de oferentes (BUENO FERRO, PABLO ESPINOSA, MUÑOZ FREILE) con Cantidad / P.Unitario / Total • Cada APU desagregado en MATERIALES / MANO DE OBRA / EQUIPO + filas TOTAL y COSTO UNITARIO APU Totales iniciales (USD): - PABLO ESPINOSA: $90,847 · 86 rubros cotizados - BUENO FERRO: $114,712 · 75 rubros - MUÑOZ FREILE: $176,923 · 70 rubros Hallazgos: - Muchos #¡DIV/0! por rubros no cotizados - Diferencias grandes en cantidades del mismo rubro (ej. excavación 0/618/3,662 m³) - Valores atípicos en precios unitarios (ej. Cemento $1.94 vs $6.70) - Capítulo 07 Cubiertas y 16 Obras Especiales no cotizados por BUENO FERRO
A7: 3 | B7: 👤 Usuario — Aclaración clave | C7: "Estos son costos de obras, no son proveedores sino el nombre de las obras. El objeto de este análisis es para crear un estándar de precios unitarios."
A8: 4 | B8: 🤖 Claude — Cambio de enfoque | C8: Reinterpretación: los 3 "oferentes" son 3 obras ya ejecutadas (BUENO FERRO, PABLO ESPINOSA, MUÑOZ FREILE) y el objetivo es construir un estándar de precios unitarios. Eso explica: - Las cantidades distintas (obras de distintos tamaños) - Los #¡DIV/0! (cada obra tuvo alcances diferentes) - La columna Q "Cantidad x Unidad" como consolidación Propuse 3 métodos: promedio simple, promedio ponderado, o mediana. Y 3 niveles de detalle: CU total, desagregado por M/MO/E, o desagregado por insumo.
A9: 5 | B9: 👤 Usuario — Decisión de alcance | C9: "Quiero que analices cada uno y que me crees después de tu análisis una propuesta de APUs que sea bien pensada." Nivel: desagregado por Materiales / MO / Equipo.
A10: 6 | B10: 🤖 Claude — Plan de 4 fases | C10: Fase 1: Extraer estructura de los 106 APUs Fase 2: Analizar rubro por rubro aplicando criterio Fase 3: Construir hoja "APU Estándar" desagregada con colores (única / dispersión / válido) Fase 4: Hoja resumen comparativa Pregunté 2 decisiones previas: - Rubros con 1 sola obra: "Incluirlos usando el dato disponible pero resaltados con un color" - Valores dispares >30%: "Señalarlos y pedir confirmación caso por caso"
A11: 7 | B11: 🤖 Claude — Fase 1 Extracción | C11: Extraje estructura completa en blob JSON: - 106 APUs con capítulo/subcapítulo/código/descripción/unidad - 689 líneas de insumos: 494 materiales + 96 mano de obra + 99 equipo - Totales y CU observados por obra
A12: 8 | B12: 🤖 Claude — Fase 2 Detección anomalías | C12: Clasifiqué todas las anomalías de precio: - Cat A (desv > 500%, 5 casos): errores de unidad obvios — descarte automático del outlier - Cat B (100-500%, 17 casos): requieren criterio técnico - Cat C (<100%, 33 casos): variación normal de mercado 28 rubros con cobertura única (1 sola obra los ejecutó). 364 insumos cotizados por 1 sola obra.
A13: 9 | B13: 👤 Usuario — Decisión operativa | C13: "Quisiera que estos casos los dejemos resaltados para realizar un análisis con mis ingenieros. Crea un reporte adicional en otra hoja para verlos."
A14: 10 | B14: 🤖 Claude — Reglas aplicadas | C14: Reglas automáticas: - 1 sola obra → uso ese valor, marco amarillo (cobertura única) - Desv <30% → promedio simple - Desv 30-100% → promedio simple - Desv 100-500% → mediana + marco naranja + agrego al Reporte - Desv >500% → asumo error de unidad, uso mayor o mediana + marca roja Hojas creadas: - "Reporte Decisiones Pendientes" con 28 casos para ingenieros - "APU Estándar" (1,263 filas) con los 106 APUs desagregados - "Resumen CU" con CU por obra + CU Estándar propuesto
A15: 11 | B15: 👤 Usuario — Iteración importante | C15: "Creo que además deberías crear una hoja solo de materiales donde colocamos el precio detallado de estos y con eso tenemos la composición de los APUs atada a esa hoja, con el fin de que si cambio el precio de los materiales los APUs se calculan automáticamente."
A16: 12 | B16: 🤖 Claude — Rediseño a modelo dinámico | C16: Decisiones tomadas: - 3 hojas separadas: BD Materiales, BD Mano de Obra, BD Equipo - Insumos consolidados (1 sola fila por insumo único, 1 PU estándar) - Crear también BD Rendimientos editable Arquitectura: BD Materiales ──┐ BD Mano de Obra ─┼──► APU Estándar ──► Resumen CU BD Equipo ──────┤ (fórmulas VLOOKUP) BD Rendimientos ─┘ Reescribí todas las celdas de APU Estándar con fórmulas: - Cantidad/Rendimiento = INDEX+MATCH a BD Rendimientos (clave única APU+Insumo+Unidad+Sección) - P.Unit = INDEX+MATCH a BD correspondiente por nombre de insumo - Subtotal = D*E - CU APU = SUMA de subtotales Consolidación: - 210 materiales únicos en BD Materiales - 95 ítems en BD Mano de Obra (92 + 3 reconstruidos) - 38 equipos en BD Equipo - 685 relaciones APU↔Insumo en BD Rendimientos
... A19: 15 | B19: 🤖 Claude — Esta hoja | C19: Creada la hoja "Historial Conversación" con este registro completo del proceso, decisiones tomadas y estado final del modelo.
B21: RESUMEN EJECUTIVO FINAL
B23: Hojas operativas del sistema:
B24: • BD Materiales | C24: 210 materiales con PU estándar · Editar columna D
B25: • BD Mano de Obra | C25: 95 ítems con PU estándar · Editar columna D
B26: • BD Equipo | C26: 38 equipos con PU estándar · Editar columna D
B27: • BD Rendimientos | C27: 685+ relaciones APU↔Insumo · Editar columna G
B28: • APU Estándar | C28: 106 APUs desagregados con fórmulas dinámicas (solo lectura)
B29: • Resumen CU | C29: Comparativo CU por obra vs CU Estándar (solo lectura)
B30: • Reporte Decisiones Pendientes | C30: 28 casos de dispersión para revisar con ingenieros
B31: • 006. Cuadro Comparativo APUs | C31: Fuente original (intacta)
B33: Código de colores aplicado:
B34: 🟡 Amarillo claro | C34: Insumo/rubro cotizado por 1 sola obra (cobertura única)
B35: 🟠 Naranja claro | C35: Insumo con dispersión >30% entre obras (revisar)
B36: 🔴 Rojo claro | C36: Rubro sin datos en ninguna obra — requiere cotización
B37: 🟢 Verde claro | C37: Celda editable en las BDs (columna D en precios, G en rendimientos)
B39: Flujo recomendado de uso:
B40: 1 | C40: Revisar Reporte Decisiones Pendientes con ingenieros y decidir valores para los 28 casos
B41: 2 | C41: Ajustar PU en BD Materiales / BD Mano de Obra / BD Equipo según decisiones
B42: 3 | C42: Afinar rendimientos en BD Rendimientos si hay dispersión
B43: 4 | C43: Validar resultados en Resumen CU
B44: 5 | C44: Usar CU Estándar como referencia para futuras licitaciones

Sheet APUs_Maestro
